Workbook

Sheet Blad1
A1: Nr. | B1: Omschrijving | C1: Categorie | D1: ontbrekend
A2: SOB1501 | B2: 2-3 wegregelklep < DN 50 flens, incl. servomotor | C2: 2-3 wegregelklep | D2: =COUNTIF(Blad2!A:A,A2) -> 0
A3: SOB1502 | B3: 2-3 wegregelklep 3/8 inch-2 inch, incl. servomotor | C3: 2-3 wegregelklep | D3: =COUNTIF(Blad2!A:A,A3) -> 0
A4: SOB1503 | B4: 2-3 wegregelklep DN 100-150 flens, incl. servomotor | C4: 2-3 wegregelklep | D4: =COUNTIF(Blad2!A:A,A4) -> 0
A5: SOB1504 | B5: 2-3 wegregelklep DN 50-100 flens, incl. servomotor | C5: 2-3 wegregelklep | D5: =COUNTIF(Blad2!A:A,A5) -> 0
A6: SOB1505 | B6: Compensator | C6: Compensator | D6: =COUNTIF(Blad2!A:A,A6) -> 0
A7: SOB1506 | B7: Detectie-instrument | C7: Detector | D7: =COUNTIF(Blad2!A:A,A7) -> 0
A8: SOB1507 | B8: Diverse appendages | C8: Appendage | D8: =COUNTIF(Blad2!A:A,A8) -> 119
A9: SOB1508 | B9: Expansievat < 18 ltr | C9: Expansievat | D9: =COUNTIF(Blad2!A:A,A9) -> 0
A10: SOB1509 | B10: Gasdrukmanometer | C10: Opnemer | D10: =COUNTIF(Blad2!A:A,A10) -> 0
A11: SOB1510 | B11: Gewichtsveiligheidstoestel < 2 inch | C11: Gewichtsveiligheidstoestel | D11: =COUNTIF(Blad2!A:A,A11) -> 0
A12: SOB1511 | B12: Gewichtsveiligheidstoestel 100-150 mm | C12: Gewichtsveiligheidstoestel | D12: =COUNTIF(Blad2!A:A,A12) -> 0
A13: SOB1512 | B13: Gewichtsveiligheidstoestel 2 inch-100 mm | C13: Gewichtsveiligheidstoestel | D13: =COUNTIF(Blad2!A:A,A13) -> 0
... A75: SOB1574 | B75: Waterafscheider 2 inch-100 mm | C75: Waterafscheider | D75: =COUNTIF(Blad2!A:A,A75) -> 0
A76: SOB1575 | B76: Waterfscheider 3/8 inch- 2 inch | C76: #N/A | D76: =COUNTIF(Blad2!A:A,A76) -> 0
A77: SOB1576 | B77: Waterverbruiksmeter 100-200 mm | C77: verbruiksmeter | D77: =COUNTIF(Blad2!A:A,A77) -> 0
A78: SOB1577 | B78: Waterverbruiksmeter 2 inch-100 mm | C78: verbruiksmeter | D78: =COUNTIF(Blad2!A:A,A78) -> 0
A79: SOB1578 | B79: Wijzerthermometer | C79: thermometer | D79: =COUNTIF(Blad2!A:A,A79) -> 0
A80: SOB1579 | B80: Bedien en beheer computersysteem | C80: computersysteem | D80: =COUNTIF(Blad2!A:A,A80) -> 0
A81: SOB1580 | B81: Beheersysteem | C81: computersysteem | D81: =COUNTIF(Blad2!A:A,A81) -> 0
A82: SOB1581 | B82: Computersysteem | C82: computersysteem | D82: =COUNTIF(Blad2!A:A,A82) -> 0
A83: SOB1582 | B83: Controleronde | C83: Controleronde | D83: =COUNTIF(Blad2!A:A,A83) -> 0
A84: SOB1583 | B84: (Rein)Watertank | C84: Reinwatertank | D84: =COUNTIF(Blad2!A:A,A84) -> 0
A85: SOB1584 | B85: Aardings- en blikseminstallatie | C85: Blikseminstallatie | D85: =COUNTIF(Blad2!A:A,A85) -> 1
A86: SOB1585 | B86: Aspiratiesysteem (ASD rookdetectie) | C86: Aspiratiesysteem | D86: =COUNTIF(Blad2!A:A,A86) -> 0
A87: SOB1586 | B87: Bassin | C87: Sprinklerinstallatie | D87: =COUNTIF(Blad2!A:A,A87) -> 0
A88: SOB1587 | B88: Beheerders PC | C88: Sprinklerinstallatie | D88: =COUNTIF(Blad2!A:A,A88) -> 0
... A167: SOB1669 | B167: Vuurwerkkluis | C167: Sprinklerinstallatie | D167: =COUNTIF(Blad2!A:A,A167) -> 0
A168: SOB1670 | B168: Afwerkingspakketten | C168: #N/A | D168: =COUNTIF(Blad2!A:A,A168) -> 0
A169: SOB1671 | B169: Balustrades en leuningen | C169: Balustrades | D169: =COUNTIF(Blad2!A:A,A169) -> 0
A170: SOB1672 | B170: Beschermlagen | C170: #N/A | D170: =COUNTIF(Blad2!A:A,A170) -> 0
A171: SOB1673 | B171: Binnenwandafwerkingen | C171: Binnenwand | D171: =COUNTIF(Blad2!A:A,A171) -> 0
A172: SOB1674 | B172: Binnenwanden | C172: Binnenwand | D172: =COUNTIF(Blad2!A:A,A172) -> 0
A173: SOB1675 | B173: Binnenwandopening | C173: Binnenwand | D173: =COUNTIF(Blad2!A:A,A173) -> 0
A174: SOB1676 | B174: Bodemvoorzieningen | C174: #N/A | D174: =COUNTIF(Blad2!A:A,A174) -> 0
A175: SOB1677 | B175: Buitenwandafwerkingen | C175: Buitenwand | D175: =COUNTIF(Blad2!A:A,A175) -> 0
A176: SOB1678 | B176: Buitenwanden | C176: Buitenwand | D176: =COUNTIF(Blad2!A:A,A176) -> 0
A177: SOB1679 | B177: Buitenwandopeningen | C177: Buitenwand | D177: =COUNTIF(Blad2!A:A,A177) -> 0
A178: SOB1680 | B178: Dakafwerkingen | C178: #N/A | D178: =COUNTIF(Blad2!A:A,A178) -> 0
A179: SOB1681 | B179: Daken | C179: Omvormer | D179: =COUNTIF(Blad2!A:A,A179) -> 0
...

Sheet Blad2
A1: SOB1507
A2: SOB2156
A3: SOB1507
A4: SOB1507
A5: SOB2284
A6: SOB1507
A7: SOB2156
A8: SOB2284
A9: SOB2156
A10: SOB1726
A11: SOB2156
A12: SOB2156
... A321: SOB1507
